Workbook

Sheet RATES & SUMMARY
A1: BK ADITYA MULTISPECIALTY HOSPITAL — JUNE 2026 BILLING SUMMARY
A3: ⚙ GLOBAL RATES — Edit these cells; all patient sheets update automatically
A4: Bed Charge (₹ per day): | B4: 1000
A5: OT Charge (₹ per hour): | B5: 1000
A7: PATIENT SUMMARY — ALL 12 BILLS • JUNE 2026
A8: Sl. | B8: Patient Name | C8: Date | D8: Doctor | E8: Procedure | F8: Anaes. | G8: OT Hrs | H8: Bed Days | I8: Consumables (₹) | J8: Bed Charge (₹) | K8: OT Charge (₹) | L8: GRAND TOTAL (₹)
A9: 28 | B9: Prabir Kumar Paul | C9: 02/06/2026 | D9: Dr. S. Gupta | E9: Excision Biopsy | F9: Local | G9: 1 | H9: 1 | I9: ='Pt28'!E999 | J9: ='Pt28'!G997 | K9: ='Pt28'!G996 | L9: ='Pt28'!G995
A10: 29 | B10: Sopna | C10: 08/06/2026 | D10: Dr. S. Gupta | E10: PIRS Spine Surgery | F10: Spinal | G10: 4 | H10: 1 | I10: ='Pt29'!E999 | J10: ='Pt29'!G997 | K10: ='Pt29'!G996 | L10: ='Pt29'!G995
A11: 30 | B11: Shankari Chakraborty | C11: 08/06/2026 | D11: Dr. K. Digga | E11: Total Knee Replacement (TKR) | F11: Spinal | G11: 3 | H11: 6 | I11: ='Pt30'!E999 | J11: ='Pt30'!G997 | K11: ='Pt30'!G996 | L11: ='Pt30'!G995
A12: 31 | B12: Kalipada Mondal | C12: 09/06/2026 | D12: Dr. S. Gupta | E12: TURP | F12: Spinal | G12: 2 | H12: 1 | I12: ='Pt31'!E999 | J12: ='Pt31'!G997 | K12: ='Pt31'!G996 | L12: ='Pt31'!G995
A13: 32 | B13: Ripusudan Sankar | C13: 09/06/2026 | D13: Dr. S. Gupta | E13: Cystoscopy | F13: Spinal | G13: 2 | H13: 1 | I13: ='Pt32'!E999 | J13: ='Pt32'!G997 | K13: ='Pt32'!G996 | L13: ='Pt32'!G995
A14: 33 | B14: Sahid Ali Joddar | C14: 12/06/2026 | D14: Dr. S. Gupta | E14: TWA | F14: General | G14: 1 | H14: 1 | I14: ='Pt33'!E999 | J14: ='Pt33'!G997 | K14: ='Pt33'!G996 | L14: ='Pt33'!G995
A15: 34 | B15: Khogen Naskar | C15: 12/06/2026 | D15: Dr. S. Gupta | E15: Cystoscopy | F15: Spinal | G15: 1 | H15: 2 | I15: ='Pt34'!E999 | J15: ='Pt34'!G997 | K15: ='Pt34'!G996 | L15: ='Pt34'!G995
A16: 35 | B16: Rahima Bibi Malla | C16: 15/06/2026 | D16: Dr. S. Gupta | E16: STG (OT) + Ward | F16: Spinal | G16: 1 | H16: 1 | I16: ='Pt35'!E999 | J16: ='Pt35'!G997 | K16: ='Pt35'!G996 | L16: ='Pt35'!G995
A17: 36 | B17: Shyamal Santra | C17: 16/06/2026 | D17: Dr. S. Gupta | E17: TURP + Ward | F17: Spinal | G17: 2 | H17: 2 | I17: ='Pt36'!E999 | J17: ='Pt36'!G997 | K17: ='Pt36'!G996 | L17: ='Pt36'!G995
A18: 37 | B18: Md. Saiful Islam | C18: 18/06/2026 | D18: Dr. K. Digga | E18: Local OT + Ward | F18: Local | G18: 1 | H18: 1 | I18: ='Pt37'!E999 | J18: ='Pt37'!G997 | K18: ='Pt37'!G996 | L18: ='Pt37'!G995
A19: 38 | B19: Depanita Sankar | C19: 21/06/2026 | D19: Dr. K. Digga | E19: Rt Femur Fracture Fixation + Ward | F19: Spinal | G19: 2 | H19: 1 | I19: ='Pt38'!E999 | J19: ='Pt38'!G997 | K19: ='Pt38'!G996 | L19: ='Pt38'!G995
A20: 39 | B20: MD Molla | C20: 22/06/2026 | D20: Dr. K. Digga | E20: Block OT + Ward | F20: Spinal | G20: 1 | H20: 1 | I20: ='Pt39'!E999 | J20: ='Pt39'!G997 | K20: ='Pt39'!G996 | L20: ='Pt39'!G995
A21: GRAND TOTAL — ALL 12 PATIENTS | I21: =SUM(I9:I20) | J21: =SUM(J9:J20) | K21: =SUM(K9:K20) | L21: =SUM(L9:L20)

Sheet Pt28
A1: BK ADITYA MULTISPECIALTY HOSPITAL — PATIENT BILL #28
A2: Patient Name | B2: Prabir Kumar Paul
A3: Date | B3: 02/06/2026
A4: Doctor | B4: Dr. S. Gupta
A5: Procedure | B5: Excision Biopsy
A6: Anaesthesia | B6: Local
A7: OT Hours | B7: 1
A8: Bed Days | B8: 1
A10: A. CONSUMABLES / MEDICINES
A11: # | B11: Item Description | C11: Qty | D11: Rate (MRP ₹) | E11: Amount (₹) | F11: Notes
A12: 1 | B12: Inj. Xone 1g (Ceftriaxone) | C12: 1 | D12: 66.64 | E12: =C12*D12 | F12: SL16 / Inj. Xone/Monocef 1g (Ceftriaxone)
A13: 2 | B13: IV Cannula 18G | C13: 1 | D13: 321 | E13: =C13*D13 | F13: SL47 / IV Cannula 18G / Venflon 18G
A14: 3 | B14: IV Cannula 20G | C14: 1 | D14: 202.55 | E14: =C14*D14 | F14: SL45 / IV Cannula 20G / Venflon 20G
A15: 4 | B15: Easyfix | C15: 1 | D15: 900 | E15: =C15*D15 | F15: SL48 / Easyfix (Adhesive Film Dressing)
A16: 5 | B16: D. Water 10ml (Sterile) | C16: 3 | D16: 3.24 | E16: =C16*D16 | F16: SL59 / D. Water 10ml (Sterile Water)
A17: 6 | B17: Syringe 10ml | C17: 2 | D17: 20 | E17: =C17*D17 | F17: SL56 / Syringe 10cc / 10ml
A18: 7 | B18: Syringe 5ml | C18: 1 | D18: 10.23 | E18: =C18*D18 | F18: SL57 / Syringe 5cc / 5ml
A19: 8 | B19: Inj. Ondem (Ondansetron) | C19: 1 | D19: 12.72 | E19: =C19*D19 | F19: SL29 / Inj. Ondem/Zofer/Zofar (Ondansetron
A20: 9 | B20: Needles 26G | C20: 2 | D20: ⚠ ENTER MRP | E20: 0 | F20: SL60 — MRP missing, enter manually
A21: 10 | B21: Betadine Lotion 100ml | C21: 1 | D21: 236.25 | E21: =C21*D21 | F21: SL69 / Betadine Lotion 100ml
A22: 11 | B22: Plain Sheet (OT) | C22: 1 | D22: 200 | E22: =C22*D22 | F22: SL83 / Plain Sheet (OT Draping)
A23: Consumables Sub-Total | E23: =SUMIF(E12:E22,">0",E12:E22) | F23: ⚠ 1 item(s) need MRP — total partial
A25: B. BED CHARGES + C. OT CHARGES
A26: Component | B26: Rate (₹) | C26: Units | D26: Amount (₹)
A27: Bed Charge (₹/day) — Bed Days in B8 | B27: ='RATES & SUMMARY'!$B$4 | C27: =B8 | D27: =B27*C27
A28: OT Charge (₹/hr) — OT Hours in B7 | B28: ='RATES & SUMMARY'!$B$5 | C28: =B7 | D28: =B28*C28
A30: GRAND TOTAL | D30: =E23+D27+D28
G995: =E23+D27+D28
G996: =D28
G997: =D27
E999: =E23

Sheet Pt29
A1: BK ADITYA MULTISPECIALTY HOSPITAL — PATIENT BILL #29
A2: Patient Name | B2: Sopna
A3: Date | B3: 08/06/2026
A4: Doctor | B4: Dr. S. Gupta
A5: Procedure | B5: PIRS Spine Surgery
A6: Anaesthesia | B6: Spinal
A7: OT Hours | B7: 4
A8: Bed Days | B8: 1
A10: A. CONSUMABLES / MEDICINES
A11: # | B11: Item Description | C11: Qty | D11: Rate (MRP ₹) | E11: Amount (₹) | F11: Notes
A12: 1 | B12: NS 500ml | C12: 2 | D12: 39.05 | E12: =C12*D12 | F12: SL1 / NS 500ml — Normal Saline
A13: 2 | B13: NS 100ml | C13: 1 | D13: 21 | E13: =C13*D13 | F13: SL3 / NS 100ml — Normal Saline 100ml
A14: 3 | B14: RL 500ml | C14: 1 | D14: 63.3 | E14: =C14*D14 | F14: SL4 / RL 500ml — Ringer's Lactate
A15: 4 | B15: Syringe 10ml | C15: 3 | D15: 20 | E15: =C15*D15 | F15: SL56 / Syringe 10cc / 10ml
A16: 5 | B16: Syringe 2ml | C16: 2 | D16: 6.04 | E16: =C16*D16 | F16: SL58 / Syringe 2cc / 2ml
A17: 6 | B17: IV Set | C17: 1 | D17: 201 | E17: =C17*D17 | F17: SL44 / IV Set / Sangoflex
A18: 7 | B18: Foley's Catheter 20 No. | C18: 1 | D18: 192.5 | E18: =C18*D18 | F18: SL52 / Foley's Catheter 20 No.
A19: 8 | B19: Inj. Ondem (Ondansetron) | C19: 1 | D19: 12.72 | E19: =C19*D19 | F19: SL29 / Inj. Ondem/Zofer/Zofar (Ondansetron
A20: 9 | B20: Inj. Pan IV (Pantoprazole) | C20: 1 | D20: 53.9 | E20: =C20*D20 | F20: SL33 / Inj. Pan 40 / Pantocid (Pantoprazol
A21: 10 | B21: Inj. Anawin Heavy 0.75% | C21: 2 | D21: 31.47 | E21: =C21*D21 | F21: SL7 / Inj. Anawin Heavy 0.75%/4ml (Bupiva
A22: 11 | B22: Gloves 7.0 Sterile | C22: 4 | D22: 91 | E22: =C22*D22 | F22: SL65 / Gloves 7.0 (Sterile Surgical)
A23: 12 | B23: Cap + Mask Set | C23: 4 | D23: ⚠ ENTER MRP | E23: 0 | F23: SL86 — MRP missing, enter manually
A24: 13 | B24: Betadine Lotion 100ml | C24: 1 | D24: 236.25 | E24: =C24*D24 | F24: SL69 / Betadine Lotion 100ml
A25: 14 | B25: Betadine Scrub 100ml | C25: 1 | D25: 236.25 | E25: =C25*D25 | F25: SL72 / Betadine Scrub 100ml
A26: Consumables Sub-Total | E26: =SUMIF(E12:E25,">0",E12:E25) | F26: ⚠ 1 item(s) need MRP — total partial
A28: B. BED CHARGES + C. OT CHARGES
A29: Component | B29: Rate (₹) | C29: Units | D29: Amount (₹)
A30: Bed Charge (₹/day) — Bed Days in B8 | B30: ='RATES & SUMMARY'!$B$4 | C30: =B8 | D30: =B30*C30
A31: OT Charge (₹/hr) — OT Hours in B7 | B31: ='RATES & SUMMARY'!$B$5 | C31: =B7 | D31: =B31*C31
A33: GRAND TOTAL | D33: =E26+D30+D31
G995: =E26+D30+D31
G996: =D31
G997: =D30
E999: =E26

Sheet Pt30
A1: BK ADITYA MULTISPECIALTY HOSPITAL — PATIENT BILL #30
A2: Patient Name | B2: Shankari Chakraborty
A3: Date | B3: 08/06/2026
A4: Doctor | B4: Dr. K. Digga
A5: Procedure | B5: Total Knee Replacement (TKR)
A6: Anaesthesia | B6: Spinal
A7: OT Hours | B7: 3
A8: Bed Days | B8: 6
A10: A. CONSUMABLES / MEDICINES
A11: # | B11: Item Description | C11: Qty | D11: Rate (MRP ₹) | E11: Amount (₹) | F11: Notes
A12: 1 | B12: Inj. Anawin Heavy 0.75% (Spinocaine) | C12: 1 | D12: 31.47 | E12: =C12*D12 | F12: SL7 / Inj. Anawin Heavy 0.75%/4ml (Bupiva
A13: 2 | B13: IV Set | C13: 2 | D13: 201 | E13: =C13*D13 | F13: SL44 / IV Set / Sangoflex
A14: 3 | B14: IV Cannula 20G | C14: 2 | D14: 202.55 | E14: =C14*D14 | F14: SL45 / IV Cannula 20G / Venflon 20G
A15: 4 | B15: Easyfix | C15: 2 | D15: 900 | E15: =C15*D15 | F15: SL48 / Easyfix (Adhesive Film Dressing)
A16: 5 | B16: Syringe 10ml | C16: 3 | D16: 20 | E16: =C16*D16 | F16: SL56 / Syringe 10cc / 10ml
A17: 6 | B17: Syringe 5ml | C17: 2 | D17: 10.23 | E17: =C17*D17 | F17: SL57 / Syringe 5cc / 5ml
A18: 7 | B18: Syringe 2ml | C18: 2 | D18: 6.04 | E18: =C18*D18 | F18: SL58 / Syringe 2cc / 2ml
A19: 8 | B19: D. Water 10ml | C19: 7 | D19: 3.24 | E19: =C19*D19 | F19: SL59 / D. Water 10ml (Sterile Water)
A20: 9 | B20: Gypsona POP Bandage 4" | C20: 2 | D20: 19.92 | E20: =C20*D20 | F20: SL85 / Gypsona POP Bandage 40G
A21: 10 | B21: Suture Ethilon 2-0 | C21: 1 | D21: 277 | E21: =C21*D21 | F21: SL77 / Suture Ethilon 2-0 / SN9336TFP
A22: 11 | B22: Suture Vicryl 1 | C22: 1 | D22: 250 | E22: =C22*D22 | F22: SL78 / Suture Vicryl 1 (2421)
A23: 12 | B23: Cap + Mask Set | C23: 6 | D23: ⚠ ENTER MRP | E23: 0 | F23: SL86 — MRP missing, enter manually
A24: 13 | B24: NS 500ml | C24: 8 | D24: 39.05 | E24: =C24*D24 | F24: SL1 / NS 500ml — Normal Saline
A25: 14 | B25: NS 100ml | C25: 6 | D25: 21 | E25: =C25*D25 | F25: SL3 / NS 100ml — Normal Saline 100ml
A26: 15 | B26: RL 500ml | C26: 1 | D26: 63.3 | E26: =C26*D26 | F26: SL4 / RL 500ml — Ringer's Lactate
A27: 16 | B27: Moli/Mackintosh Sheet | C27: 1 | D27: 150 | E27: =C27*D27 | F27: SL87 / Moli / Mackintosh Sheet
A28: 17 | B28: Inj. Neomol IV 10ml | C28: 7 | D28: 42.8 | E28: =C28*D28 | F28: SL28 / Inj. Neomol IV 10ml (PCM IV)
A29: 18 | B29: Foley's Catheter 16 No. | C29: 1 | D29: 174 | E29: =C29*D29 | F29: SL50 / Foley's Catheter 16 No.
A30: 19 | B30: Uro Bag | C30: 1 | D30: 361 | E30: =C30*D30 | F30: SL49 / Uro Bag
A31: 20 | B31: Inj. Ondem 2ml | C31: 7 | D31: 12.72 | E31: =C31*D31 | F31: SL29 / Inj. Ondem/Zofer/Zofar (Ondansetron
A32: 21 | B32: Inj. Pan IV | C32: 6 | D32: 53.9 | E32: =C32*D32 | F32: SL33 / Inj. Pan 40 / Pantocid (Pantoprazol
A33: 22 | B33: Inj. Xone 1g | C33: 4 | D33: 66.64 | E33: =C33*D33 | F33: SL16 / Inj. Xone/Monocef 1g (Ceftriaxone)
A34: 23 | B34: Inj. Diclofenac AQ (Justin) | C34: 4 | D34: 23.8 | E34: =C34*D34 | F34: SL22 / Inj. Dynapar/Justin AQ (Diclofenac
A35: 24 | B35: Inj. PCM 100ml (Paracetamol IV) | C35: 3 | D35: 591.3 | E35: =C35*D35 | F35: SL27 / Inj. PCM 100ml (Paracetamol IV)
... A42: 31 | B42: Betadine Lotion 100ml | C42: 1 | D42: 236.25 | E42: =C42*D42 | F42: SL69 / Betadine Lotion 100ml
A43: 32 | B43: Betadine Ointment 40g | C43: 1 | D43: ⚠ ENTER MRP | E43: 0 | F43: SL71 — MRP missing, enter manually
A44: Consumables Sub-Total | E44: =SUMIF(E12:E43,">0",E12:E43) | F44: ⚠ 2 item(s) need MRP — total partial
A46: B. BED CHARGES + C. OT CHARGES
A47: Component | B47: Rate (₹) | C47: Units | D47: Amount (₹)
A48: Bed Charge (₹/day) — Bed Days in B8 | B48: ='RATES & SUMMARY'!$B$4 | C48: =B8 | D48: =B48*C48
...

Sheet Pt31
A1: BK ADITYA MULTISPECIALTY HOSPITAL — PATIENT BILL #31
A2: Patient Name | B2: Kalipada Mondal
A3: Date | B3: 09/06/2026
A4: Doctor | B4: Dr. S. Gupta
A5: Procedure | B5: TURP
A6: Anaesthesia | B6: Spinal
A7: OT Hours | B7: 2
A8: Bed Days | B8: 1
A10: A. CONSUMABLES / MEDICINES
A11: # | B11: Item Description | C11: Qty | D11: Rate (MRP ₹) | E11: Amount (₹) | F11: Notes
A12: 1 | B12: IV Cannula 18G | C12: 1 | D12: 321 | E12: =C12*D12 | F12: SL47 / IV Cannula 18G / Venflon 18G
A13: 2 | B13: Easyfix | C13: 1 | D13: 900 | E13: =C13*D13 | F13: SL48 / Easyfix (Adhesive Film Dressing)
A14: 3 | B14: NS 500ml | C14: 2 | D14: 39.05 | E14: =C14*D14 | F14: SL1 / NS 500ml — Normal Saline
A15: 4 | B15: NS 1000ml (Glycine sub) | C15: 3 | D15: 62.22 | E15: =C15*D15 | F15: SL2 / NS 1000ml — Normal Saline 1L
A16: 5 | B16: NS 100ml | C16: 1 | D16: 21 | E16: =C16*D16 | F16: SL3 / NS 100ml — Normal Saline 100ml
A17: 6 | B17: Syringe 10ml | C17: 2 | D17: 20 | E17: =C17*D17 | F17: SL56 / Syringe 10cc / 10ml
A18: 7 | B18: Syringe 2ml | C18: 2 | D18: 6.04 | E18: =C18*D18 | F18: SL58 / Syringe 2cc / 2ml
A19: 8 | B19: D. Water 10ml | C19: 2 | D19: 3.24 | E19: =C19*D19 | F19: SL59 / D. Water 10ml (Sterile Water)
A20: 9 | B20: Inj. Anawin Heavy 0.75% | C20: 1 | D20: 31.47 | E20: =C20*D20 | F20: SL7 / Inj. Anawin Heavy 0.75%/4ml (Bupiva
A21: 10 | B21: Inj. Atropine | C21: 1 | D21: 7.3 | E21: =C21*D21 | F21: SL11 / Inj. Atropine 1ml
A22: 11 | B22: Foley's Catheter 20 No. | C22: 1 | D22: 192.5 | E22: =C22*D22 | F22: SL52 / Foley's Catheter 20 No.
A23: 12 | B23: Uro Bag | C23: 1 | D23: 361 | E23: =C23*D23 | F23: SL49 / Uro Bag
... A31: 20 | B31: Surgical Blade No. 10 | C31: 1 | D31: 750 | E31: =C31*D31 | F31: SL81 / Surgical Blade No. 10
A32: Consumables Sub-Total | E32: =SUMIF(E12:E31,">0",E12:E31) | F32: All items priced ✓
A34: B. BED CHARGES + C. OT CHARGES
A35: Component | B35: Rate (₹) | C35: Units | D35: Amount (₹)
A36: Bed Charge (₹/day) — Bed Days in B8 | B36: ='RATES & SUMMARY'!$B$4 | C36: =B8 | D36: =B36*C36
A37: OT Charge (₹/hr) — OT Hours in B7 | B37: ='RATES & SUMMARY'!$B$5 | C37: =B7 | D37: =B37*C37
A39: GRAND TOTAL | D39: =E32+D36+D37
G995: =E32+D36+D37
G996: =D37
G997: =D36
E999: =E32

Sheet Pt32
A1: BK ADITYA MULTISPECIALTY HOSPITAL — PATIENT BILL #32
A2: Patient Name | B2: Ripusudan Sankar
A3: Date | B3: 09/06/2026
A4: Doctor | B4: Dr. S. Gupta
A5: Procedure | B5: Cystoscopy
A6: Anaesthesia | B6: Spinal
A7: OT Hours | B7: 2
A8: Bed Days | B8: 1
A10: A. CONSUMABLES / MEDICINES
A11: # | B11: Item Description | C11: Qty | D11: Rate (MRP ₹) | E11: Amount (₹) | F11: Notes
A12: 1 | B12: IV Cannula 20G | C12: 1 | D12: 202.55 | E12: =C12*D12 | F12: SL45 / IV Cannula 20G / Venflon 20G
A13: 2 | B13: Easyfix | C13: 1 | D13: 900 | E13: =C13*D13 | F13: SL48 / Easyfix (Adhesive Film Dressing)
A14: 3 | B14: NS 100ml | C14: 1 | D14: 21 | E14: =C14*D14 | F14: SL3 / NS 100ml — Normal Saline 100ml
A15: 4 | B15: IV Set | C15: 1 | D15: 201 | E15: =C15*D15 | F15: SL44 / IV Set / Sangoflex
A16: 5 | B16: NS 500ml | C16: 1 | D16: 39.05 | E16: =C16*D16 | F16: SL1 / NS 500ml — Normal Saline
A17: 6 | B17: Gloves 7.0 Sterile | C17: 2 | D17: 91 | E17: =C17*D17 | F17: SL65 / Gloves 7.0 (Sterile Surgical)
A18: 7 | B18: Betadine Lotion 100ml | C18: 1 | D18: 236.25 | E18: =C18*D18 | F18: SL69 / Betadine Lotion 100ml
A19: Consumables Sub-Total | E19: =SUMIF(E12:E18,">0",E12:E18) | F19: All items priced ✓
A21: B. BED CHARGES + C. OT CHARGES
A22: Component | B22: Rate (₹) | C22: Units | D22: Amount (₹)
A23: Bed Charge (₹/day) — Bed Days in B8 | B23: ='RATES & SUMMARY'!$B$4 | C23: =B8 | D23: =B23*C23
A24: OT Charge (₹/hr) — OT Hours in B7 | B24: ='RATES & SUMMARY'!$B$5 | C24: =B7 | D24: =B24*C24
A26: GRAND TOTAL | D26: =E19+D23+D24
G995: =E19+D23+D24
G996: =D24
G997: =D23
E999: =E19

Sheet Pt33
A1: BK ADITYA MULTISPECIALTY HOSPITAL — PATIENT BILL #33
A2: Patient Name | B2: Sahid Ali Joddar
A3: Date | B3: 12/06/2026
A4: Doctor | B4: Dr. S. Gupta
A5: Procedure | B5: TWA
A6: Anaesthesia | B6: General
A7: OT Hours | B7: 1
A8: Bed Days | B8: 1
A10: A. CONSUMABLES / MEDICINES
A11: # | B11: Item Description | C11: Qty | D11: Rate (MRP ₹) | E11: Amount (₹) | F11: Notes
A12: 1 | B12: IV Cannula 20G | C12: 1 | D12: 202.55 | E12: =C12*D12 | F12: SL45 / IV Cannula 20G / Venflon 20G
A13: 2 | B13: Easyfix | C13: 1 | D13: 900 | E13: =C13*D13 | F13: SL48 / Easyfix (Adhesive Film Dressing)
A14: 3 | B14: D. Water 10ml | C14: 1 | D14: 3.24 | E14: =C14*D14 | F14: SL59 / D. Water 10ml (Sterile Water)
A15: 4 | B15: Syringe 5ml | C15: 1 | D15: 10.23 | E15: =C15*D15 | F15: SL57 / Syringe 5cc / 5ml
A16: 5 | B16: NS 500ml | C16: 1 | D16: 39.05 | E16: =C16*D16 | F16: SL1 / NS 500ml — Normal Saline
A17: 6 | B17: Betadine Lotion 50ml | C17: 1 | D17: 118.13 | E17: =C17*D17 | F17: SL70 / Betadine Lotion 50ml
A18: Consumables Sub-Total | E18: =SUMIF(E12:E17,">0",E12:E17) | F18: All items priced ✓
A20: B. BED CHARGES + C. OT CHARGES
A21: Component | B21: Rate (₹) | C21: Units | D21: Amount (₹)
A22: Bed Charge (₹/day) — Bed Days in B8 | B22: ='RATES & SUMMARY'!$B$4 | C22: =B8 | D22: =B22*C22
A23: OT Charge (₹/hr) — OT Hours in B7 | B23: ='RATES & SUMMARY'!$B$5 | C23: =B7 | D23: =B23*C23
A25: GRAND TOTAL | D25: =E18+D22+D23
G995: =E18+D22+D23
G996: =D23
G997: =D22
E999: =E18

Sheet Pt34
A1: BK ADITYA MULTISPECIALTY HOSPITAL — PATIENT BILL #34
A2: Patient Name | B2: Khogen Naskar
A3: Date | B3: 12/06/2026
A4: Doctor | B4: Dr. S. Gupta
A5: Procedure | B5: Cystoscopy
A6: Anaesthesia | B6: Spinal
A7: OT Hours | B7: 1
A8: Bed Days | B8: 2
A10: A. CONSUMABLES / MEDICINES
A11: # | B11: Item Description | C11: Qty | D11: Rate (MRP ₹) | E11: Amount (₹) | F11: Notes
A12: 1 | B12: IV Cannula 20G | C12: 1 | D12: 202.55 | E12: =C12*D12 | F12: SL45 / IV Cannula 20G / Venflon 20G
A13: 2 | B13: Inj. Ondem | C13: 1 | D13: 12.72 | E13: =C13*D13 | F13: SL29 / Inj. Ondem/Zofer/Zofar (Ondansetron
A14: 3 | B14: Inj. Pan IV | C14: 1 | D14: 53.9 | E14: =C14*D14 | F14: SL33 / Inj. Pan 40 / Pantocid (Pantoprazol
A15: 4 | B15: Inj. MEM (Meropenem) | C15: 1 | D15: 15.9 | E15: =C15*D15 | F15: SL18 / Inj. MEM (Meropenem)
A16: 5 | B16: Syringe 10ml | C16: 1 | D16: 20 | E16: =C16*D16 | F16: SL56 / Syringe 10cc / 10ml
A17: 6 | B17: Easyfix | C17: 1 | D17: 900 | E17: =C17*D17 | F17: SL48 / Easyfix (Adhesive Film Dressing)
A18: 7 | B18: IV Set | C18: 1 | D18: 201 | E18: =C18*D18 | F18: SL44 / IV Set / Sangoflex
A19: 8 | B19: NS 100ml | C19: 1 | D19: 21 | E19: =C19*D19 | F19: SL3 / NS 100ml — Normal Saline 100ml
A20: 9 | B20: Cap + Mask Set | C20: 1 | D20: ⚠ ENTER MRP | E20: 0 | F20: SL86 — MRP missing, enter manually
A21: 10 | B21: Betadine Lotion 100ml | C21: 1 | D21: 236.25 | E21: =C21*D21 | F21: SL69 / Betadine Lotion 100ml
A22: Consumables Sub-Total | E22: =SUMIF(E12:E21,">0",E12:E21) | F22: ⚠ 1 item(s) need MRP — total partial
A24: B. BED CHARGES + C. OT CHARGES
A25: Component | B25: Rate (₹) | C25: Units | D25: Amount (₹)
A26: Bed Charge (₹/day) — Bed Days in B8 | B26: ='RATES & SUMMARY'!$B$4 | C26: =B8 | D26: =B26*C26
A27: OT Charge (₹/hr) — OT Hours in B7 | B27: ='RATES & SUMMARY'!$B$5 | C27: =B7 | D27: =B27*C27
A29: GRAND TOTAL | D29: =E22+D26+D27
G995: =E22+D26+D27
G996: =D27
G997: =D26
E999: =E22

Sheet Pt35
A1: BK ADITYA MULTISPECIALTY HOSPITAL — PATIENT BILL #35
A2: Patient Name | B2: Rahima Bibi Malla
A3: Date | B3: 15/06/2026
A4: Doctor | B4: Dr. S. Gupta
A5: Procedure | B5: STG (OT) + Ward
A6: Anaesthesia | B6: Spinal
A7: OT Hours | B7: 1
A8: Bed Days | B8: 1
A10: A. CONSUMABLES / MEDICINES
A11: # | B11: Item Description | C11: Qty | D11: Rate (MRP ₹) | E11: Amount (₹) | F11: Notes
A12: 1 | B12: NS 500ml | C12: 5 | D12: 39.05 | E12: =C12*D12 | F12: SL1 / NS 500ml — Normal Saline
A13: 2 | B13: NS 100ml | C13: 5 | D13: 21 | E13: =C13*D13 | F13: SL3 / NS 100ml — Normal Saline 100ml
A14: 3 | B14: NS 1000ml | C14: 2 | D14: 62.22 | E14: =C14*D14 | F14: SL2 / NS 1000ml — Normal Saline 1L
A15: 4 | B15: RL 500ml | C15: 1 | D15: 63.3 | E15: =C15*D15 | F15: SL4 / RL 500ml — Ringer's Lactate
A16: 5 | B16: Syringe 2ml | C16: 2 | D16: 6.04 | E16: =C16*D16 | F16: SL58 / Syringe 2cc / 2ml
A17: 6 | B17: Inj. Anawin Heavy 0.75% | C17: 1 | D17: 31.47 | E17: =C17*D17 | F17: SL7 / Inj. Anawin Heavy 0.75%/4ml (Bupiva
A18: 7 | B18: Inj. Atropine | C18: 1 | D18: 7.3 | E18: =C18*D18 | F18: SL11 / Inj. Atropine 1ml
A19: 8 | B19: Inj. Midazolam | C19: 1 | D19: 31.03 | E19: =C19*D19 | F19: SL9 / Inj. Midazolam 5ml (Mezolam)
A20: 9 | B20: Inj. Oxytocin | C20: 1 | D20: 19.03 | E20: =C20*D20 | F20: SL35 / Inj. Oxytocin/Syntocinon 1ml
A21: 10 | B21: Inj. PCM 100ml | C21: 3 | D21: 591.3 | E21: =C21*D21 | F21: SL27 / Inj. PCM 100ml (Paracetamol IV)
A22: 11 | B22: OT Mop / Abd Swab | C22: 2 | D22: 165 | E22: =C22*D22 | F22: SL64 / OT Mop / Abd. Swab
A23: 12 | B23: Gauze Pieces (Sterile) | C23: 4 | D23: 14 | E23: =C23*D23 | F23: SL63 / Gauze Pieces (Sterile)
A24: 13 | B24: Gloves 7.0 Sterile | C24: 8 | D24: 91 | E24: =C24*D24 | F24: SL65 / Gloves 7.0 (Sterile Surgical)
A25: 14 | B25: O2 (per use) | C25: 2 | D25: ⚠ ENTER MRP | E25: 0 | F25: SL96 — MRP missing, enter manually
A26: 15 | B26: Betadine Lotion 100ml | C26: 1 | D26: 236.25 | E26: =C26*D26 | F26: SL69 / Betadine Lotion 100ml
A27: 16 | B27: Betadine Scrub 100ml | C27: 1 | D27: 236.25 | E27: =C27*D27 | F27: SL72 / Betadine Scrub 100ml
A28: 17 | B28: Plain Sheet (OT) | C28: 3 | D28: 200 | E28: =C28*D28 | F28: SL83 / Plain Sheet (OT Draping)
A29: 18 | B29: Suture Vicryl 1 | C29: 1 | D29: 250 | E29: =C29*D29 | F29: SL78 / Suture Vicryl 1 (2421)
A30: 19 | B30: Surgical Blade No. 10 | C30: 1 | D30: 750 | E30: =C30*D30 | F30: SL81 / Surgical Blade No. 10
A31: 20 | B31: Foley's Catheter 18 No. | C31: 1 | D31: 192.5 | E31: =C31*D31 | F31: SL51 / Foley's Catheter 18 No.
A32: 21 | B32: Uro Bag | C32: 1 | D32: 361 | E32: =C32*D32 | F32: SL49 / Uro Bag
A33: 22 | B33: IV Set | C33: 1 | D33: 201 | E33: =C33*D33 | F33: SL44 / IV Set / Sangoflex
A34: 23 | B34: IV Cannula 20G | C34: 1 | D34: 202.55 | E34: =C34*D34 | F34: SL45 / IV Cannula 20G / Venflon 20G
A35: 24 | B35: Easyfix | C35: 1 | D35: 900 | E35: =C35*D35 | F35: SL48 / Easyfix (Adhesive Film Dressing)
A36: 25 | B36: Syringe 10ml | C36: 1 | D36: 20 | E36: =C36*D36 | F36: SL56 / Syringe 10cc / 10ml
A37: 26 | B37: Syringe 5ml | C37: 1 | D37: 10.23 | E37: =C37*D37 | F37: SL57 / Syringe 5cc / 5ml
... A42: 31 | B42: D. Water 10ml | C42: 1 | D42: 3.24 | E42: =C42*D42 | F42: SL59 / D. Water 10ml (Sterile Water)
A43: Consumables Sub-Total | E43: =SUMIF(E12:E42,">0",E12:E42) | F43: ⚠ 1 item(s) need MRP — total partial
A45: B. BED CHARGES + C. OT CHARGES
A46: Component | B46: Rate (₹) | C46: Units | D46: Amount (₹)
...

Sheet Pt36
A1: BK ADITYA MULTISPECIALTY HOSPITAL — PATIENT BILL #36
A2: Patient Name | B2: Shyamal Santra
A3: Date | B3: 16/06/2026
A4: Doctor | B4: Dr. S. Gupta
A5: Procedure | B5: TURP + Ward
A6: Anaesthesia | B6: Spinal
A7: OT Hours | B7: 2
A8: Bed Days | B8: 2
A10: A. CONSUMABLES / MEDICINES
A11: # | B11: Item Description | C11: Qty | D11: Rate (MRP ₹) | E11: Amount (₹) | F11: Notes
A12: 1 | B12: IV Cannula 18G | C12: 1 | D12: 321 | E12: =C12*D12 | F12: SL47 / IV Cannula 18G / Venflon 18G
A13: 2 | B13: Easyfix | C13: 1 | D13: 900 | E13: =C13*D13 | F13: SL48 / Easyfix (Adhesive Film Dressing)
A14: 3 | B14: NS 1000ml | C14: 4 | D14: 62.22 | E14: =C14*D14 | F14: SL2 / NS 1000ml — Normal Saline 1L
A15: 4 | B15: NS 500ml | C15: 1 | D15: 39.05 | E15: =C15*D15 | F15: SL1 / NS 500ml — Normal Saline
A16: 5 | B16: Syringe 2ml | C16: 2 | D16: 6.04 | E16: =C16*D16 | F16: SL58 / Syringe 2cc / 2ml
A17: 6 | B17: Inj. Anawin Heavy 0.75% | C17: 1 | D17: 31.47 | E17: =C17*D17 | F17: SL7 / Inj. Anawin Heavy 0.75%/4ml (Bupiva
A18: 7 | B18: Inj. Atropine | C18: 1 | D18: 7.3 | E18: =C18*D18 | F18: SL11 / Inj. Atropine 1ml
A19: 8 | B19: Inj. Midazolam | C19: 1 | D19: 31.03 | E19: =C19*D19 | F19: SL9 / Inj. Midazolam 5ml (Mezolam)
A20: 9 | B20: Foley's Catheter 20 No. | C20: 1 | D20: 192.5 | E20: =C20*D20 | F20: SL52 / Foley's Catheter 20 No.
A21: 10 | B21: Uro Bag | C21: 1 | D21: 361 | E21: =C21*D21 | F21: SL49 / Uro Bag
A22: 11 | B22: Betadine Lotion 100ml | C22: 1 | D22: 236.25 | E22: =C22*D22 | F22: SL69 / Betadine Lotion 100ml
A23: 12 | B23: OT Mop / Abd Swab | C23: 2 | D23: 165 | E23: =C23*D23 | F23: SL64 / OT Mop / Abd. Swab
... A30: 19 | B30: IV Set | C30: 1 | D30: 201 | E30: =C30*D30 | F30: SL44 / IV Set / Sangoflex
A31: 20 | B31: Cap + Mask Set | C31: 3 | D31: ⚠ ENTER MRP | E31: 0 | F31: SL86 — MRP missing, enter manually
A32: 21 | B32: Pulse Oximeter (per use) | C32: 1 | D32: ⚠ ENTER MRP | E32: 0 | F32: SL97 — MRP missing, enter manually
A33: Consumables Sub-Total | E33: =SUMIF(E12:E32,">0",E12:E32) | F33: ⚠ 2 item(s) need MRP — total partial
A35: B. BED CHARGES + C. OT CHARGES
A36: Component | B36: Rate (₹) | C36: Units | D36: Amount (₹)
A37: Bed Charge (₹/day) — Bed Days in B8 | B37: ='RATES & SUMMARY'!$B$4 | C37: =B8 | D37: =B37*C37
A38: OT Charge (₹/hr) — OT Hours in B7 | B38: ='RATES & SUMMARY'!$B$5 | C38: =B7 | D38: =B38*C38
A40: GRAND TOTAL | D40: =E33+D37+D38
G995: =E33+D37+D38
G996: =D38
G997: =D37
E999: =E33

Sheet Pt37
A1: BK ADITYA MULTISPECIALTY HOSPITAL — PATIENT BILL #37
A2: Patient Name | B2: Md. Saiful Islam
A3: Date | B3: 18/06/2026
A4: Doctor | B4: Dr. K. Digga
A5: Procedure | B5: Local OT + Ward
A6: Anaesthesia | B6: Local
A7: OT Hours | B7: 1
A8: Bed Days | B8: 1
A10: A. CONSUMABLES / MEDICINES
A11: # | B11: Item Description | C11: Qty | D11: Rate (MRP ₹) | E11: Amount (₹) | F11: Notes
A12: 1 | B12: Foley's Catheter 20 No. | C12: 2 | D12: 192.5 | E12: =C12*D12 | F12: SL52 / Foley's Catheter 20 No.
A13: 2 | B13: Betadine Lotion 100ml | C13: 1 | D13: 236.25 | E13: =C13*D13 | F13: SL69 / Betadine Lotion 100ml
A14: 3 | B14: OT Mop / Abd Swab | C14: 1 | D14: 165 | E14: =C14*D14 | F14: SL64 / OT Mop / Abd. Swab
A15: 4 | B15: Inj. Lox 2% (Lignocaine) | C15: 1 | D15: 37.95 | E15: =C15*D15 | F15: SL14 / Inj. Lox 2% Jelly (Lignocaine)
A16: 5 | B16: Gloves 7.0 Sterile | C16: 3 | D16: 91 | E16: =C16*D16 | F16: SL65 / Gloves 7.0 (Sterile Surgical)
A17: 6 | B17: Cap + Mask Set | C17: 2 | D17: ⚠ ENTER MRP | E17: 0 | F17: SL86 — MRP missing, enter manually
A18: 7 | B18: NS 500ml | C18: 4 | D18: 39.05 | E18: =C18*D18 | F18: SL1 / NS 500ml — Normal Saline
A19: 8 | B19: Roller Bandage 6" | C19: 3 | D19: 67.5 | E19: =C19*D19 | F19: SL74 / Roller Bandage 6" (Crepe)
A20: 9 | B20: Inj. Xone 1g | C20: 3 | D20: 66.64 | E20: =C20*D20 | F20: SL16 / Inj. Xone/Monocef 1g (Ceftriaxone)
A21: 10 | B21: Inj. Ondem | C21: 1 | D21: 12.72 | E21: =C21*D21 | F21: SL29 / Inj. Ondem/Zofer/Zofar (Ondansetron
A22: 11 | B22: Inj. Pan IV | C22: 2 | D22: 53.9 | E22: =C22*D22 | F22: SL33 / Inj. Pan 40 / Pantocid (Pantoprazol
A23: 12 | B23: Syringe 2ml | C23: 1 | D23: 6.04 | E23: =C23*D23 | F23: SL58 / Syringe 2cc / 2ml
A24: 13 | B24: NS 100ml | C24: 2 | D24: 21 | E24: =C24*D24 | F24: SL3 / NS 100ml — Normal Saline 100ml
A25: Consumables Sub-Total | E25: =SUMIF(E12:E24,">0",E12:E24) | F25: ⚠ 1 item(s) need MRP — total partial
A27: B. BED CHARGES + C. OT CHARGES
A28: Component | B28: Rate (₹) | C28: Units | D28: Amount (₹)
A29: Bed Charge (₹/day) — Bed Days in B8 | B29: ='RATES & SUMMARY'!$B$4 | C29: =B8 | D29: =B29*C29
A30: OT Charge (₹/hr) — OT Hours in B7 | B30: ='RATES & SUMMARY'!$B$5 | C30: =B7 | D30: =B30*C30
A32: GRAND TOTAL | D32: =E25+D29+D30
G995: =E25+D29+D30
G996: =D30
G997: =D29
E999: =E25

Sheet Pt38
A1: BK ADITYA MULTISPECIALTY HOSPITAL — PATIENT BILL #38
A2: Patient Name | B2: Depanita Sankar
A3: Date | B3: 21/06/2026
A4: Doctor | B4: Dr. K. Digga
A5: Procedure | B5: Rt Femur Fracture Fixation + Ward
A6: Anaesthesia | B6: Spinal
A7: OT Hours | B7: 2
A8: Bed Days | B8: 1
A10: A. CONSUMABLES / MEDICINES
A11: # | B11: Item Description | C11: Qty | D11: Rate (MRP ₹) | E11: Amount (₹) | F11: Notes
A12: 1 | B12: Inj. Xone 1g | C12: 6 | D12: 66.64 | E12: =C12*D12 | F12: SL16 / Inj. Xone/Monocef 1g (Ceftriaxone)
A13: 2 | B13: Inj. Pan IV | C13: 3 | D13: 53.9 | E13: =C13*D13 | F13: SL33 / Inj. Pan 40 / Pantocid (Pantoprazol
A14: 3 | B14: Inj. Ondem 2ml | C14: 2 | D14: 12.72 | E14: =C14*D14 | F14: SL29 / Inj. Ondem/Zofer/Zofar (Ondansetron
A15: 4 | B15: Easyfix | C15: 1 | D15: 900 | E15: =C15*D15 | F15: SL48 / Easyfix (Adhesive Film Dressing)
A16: 5 | B16: IV Cannula 22G | C16: 2 | D16: 202.55 | E16: =C16*D16 | F16: SL46 / IV Cannula 22G
A17: 6 | B17: NS 500ml | C17: 2 | D17: 39.05 | E17: =C17*D17 | F17: SL1 / NS 500ml — Normal Saline
A18: 7 | B18: IV Set | C18: 1 | D18: 201 | E18: =C18*D18 | F18: SL44 / IV Set / Sangoflex
A19: 8 | B19: Syringe 2ml | C19: 1 | D19: 6.04 | E19: =C19*D19 | F19: SL58 / Syringe 2cc / 2ml
A20: 9 | B20: Syringe 10ml | C20: 1 | D20: 20 | E20: =C20*D20 | F20: SL56 / Syringe 10cc / 10ml
A21: 10 | B21: D. Water 10ml | C21: 2 | D21: 3.24 | E21: =C21*D21 | F21: SL59 / D. Water 10ml (Sterile Water)
A22: 11 | B22: Inj. Tramadol 2ml | C22: 4 | D22: 12.56 | E22: =C22*D22 | F22: SL25 / Inj. Tramadol 50mg
A23: 12 | B23: O2 (4 hours) | C23: 1 | D23: ⚠ ENTER MRP | E23: 0 | F23: SL96 — MRP missing, enter manually
A24: 13 | B24: NS 100ml | C24: 7 | D24: 21 | E24: =C24*D24 | F24: SL3 / NS 100ml — Normal Saline 100ml
A25: 14 | B25: DNS 500ml | C25: 1 | D25: 40.12 | E25: =C25*D25 | F25: SL6 / D5 500ml — Dextrose 5%
A26: Consumables Sub-Total | E26: =SUMIF(E12:E25,">0",E12:E25) | F26: ⚠ 1 item(s) need MRP — total partial
A28: B. BED CHARGES + C. OT CHARGES
A29: Component | B29: Rate (₹) | C29: Units | D29: Amount (₹)
A30: Bed Charge (₹/day) — Bed Days in B8 | B30: ='RATES & SUMMARY'!$B$4 | C30: =B8 | D30: =B30*C30
A31: OT Charge (₹/hr) — OT Hours in B7 | B31: ='RATES & SUMMARY'!$B$5 | C31: =B7 | D31: =B31*C31
A33: GRAND TOTAL | D33: =E26+D30+D31
G995: =E26+D30+D31
G996: =D31
G997: =D30
E999: =E26

Sheet Pt39
A1: BK ADITYA MULTISPECIALTY HOSPITAL — PATIENT BILL #39
A2: Patient Name | B2: MD Molla
A3: Date | B3: 22/06/2026
A4: Doctor | B4: Dr. K. Digga
A5: Procedure | B5: Block OT + Ward
A6: Anaesthesia | B6: Spinal
A7: OT Hours | B7: 1
A8: Bed Days | B8: 1
A10: A. CONSUMABLES / MEDICINES
A11: # | B11: Item Description | C11: Qty | D11: Rate (MRP ₹) | E11: Amount (₹) | F11: Notes
A12: 1 | B12: Easyfix | C12: 1 | D12: 900 | E12: =C12*D12 | F12: SL48 / Easyfix (Adhesive Film Dressing)
A13: 2 | B13: IV Cannula 20G | C13: 1 | D13: 202.55 | E13: =C13*D13 | F13: SL45 / IV Cannula 20G / Venflon 20G
A14: 3 | B14: IV Set | C14: 1 | D14: 201 | E14: =C14*D14 | F14: SL44 / IV Set / Sangoflex
A15: 4 | B15: Inj. Ondem | C15: 2 | D15: 12.72 | E15: =C15*D15 | F15: SL29 / Inj. Ondem/Zofer/Zofar (Ondansetron
A16: 5 | B16: Inj. Pan IV | C16: 2 | D16: 53.9 | E16: =C16*D16 | F16: SL33 / Inj. Pan 40 / Pantocid (Pantoprazol
A17: 6 | B17: Inj. Xone 1g | C17: 2 | D17: 66.64 | E17: =C17*D17 | F17: SL16 / Inj. Xone/Monocef 1g (Ceftriaxone)
A18: 7 | B18: D. Water 10ml | C18: 1 | D18: 3.24 | E18: =C18*D18 | F18: SL59 / D. Water 10ml (Sterile Water)
A19: 8 | B19: NS 500ml | C19: 2 | D19: 39.05 | E19: =C19*D19 | F19: SL1 / NS 500ml — Normal Saline
A20: 9 | B20: Inj. Diclofenac AQ (Justin) | C20: 2 | D20: 23.8 | E20: =C20*D20 | F20: SL22 / Inj. Dynapar/Justin AQ (Diclofenac
A21: Consumables Sub-Total | E21: =SUMIF(E12:E20,">0",E12:E20) | F21: All items priced ✓
A23: B. BED CHARGES + C. OT CHARGES
A24: Component | B24: Rate (₹) | C24: Units | D24: Amount (₹)
A25: Bed Charge (₹/day) — Bed Days in B8 | B25: ='RATES & SUMMARY'!$B$4 | C25: =B8 | D25: =B25*C25
A26: OT Charge (₹/hr) — OT Hours in B7 | B26: ='RATES & SUMMARY'!$B$5 | C26: =B7 | D26: =B26*C26
A28: GRAND TOTAL | D28: =E21+D25+D26
G995: =E21+D25+D26
G996: =D26
G997: =D25
E999: =E21
